<?xml version="1.0" ?>
<robot name="moving_base" version="1.0">
  <material name="grey">
    <color rgba="0.7 0.7 0.7 1.0"/>
  </material>
  <material name="dark">
    <color rgba="0.3 0.3 0.3 1.0"/>
  </material>
  <material name="light_black">
    <color rgba="0.4 0.4 0.4 1.0"/>
  </material>
  <gazebo reference="base_link_mb">
    <sensor name="base_link_mb" type="contact">
      <update_rate>1000.0</update_rate>
      <always_on>true</always_on>
      <contact>
        <collision>base_footprint_fixed_joint_lump__base_link_collision</collision>
      </contact>
      <plugin filename="libgazebo_ros_bumper.so" name="base_link_contact_sensor_plugin">
        <bumperTopicName>contact</bumperTopicName>
        <frameName>world</frameName>
      </plugin>
    </sensor>
  </gazebo>
  <gazebo reference="base_link_mb">
    <material>Gazebo/DarkGrey</material>
  </gazebo>
  <gazebo reference="wheel_left_link">
    <mu1 value="1.0"/>
    <mu2 value="1.0"/>
    <kp value="10000000.0"/>
    <kd value="1.0"/>
    <minDepth>0.001</minDepth>
    <maxVel>0.1</maxVel>
    <fdir1>1 0 0</fdir1>
    <material>Gazebo/FlatBlack</material>
  </gazebo>
  <gazebo reference="wheel_right_link">
    <mu1 value="1.0"/>
    <mu2 value="1.0"/>
    <kp value="10000000.0"/>
    <kd value="1.0"/>
    <minDepth>0.001</minDepth>
    <maxVel>0.1</maxVel>
    <fdir1>1 0 0</fdir1>
    <material>Gazebo/FlatBlack</material>
  </gazebo>
  <gazebo reference="caster_back_right_link">
    <mu1>0.01</mu1>
    <mu2>0.01</mu2>
    <kp>1000000.0</kp>
    <kd>100.0</kd>
    <minDepth>0.001</minDepth>
    <maxVel>1.0</maxVel>
    <material>Gazebo/FlatBlack</material>
  </gazebo>
  <gazebo reference="caster_back_left_link">
    <mu1>0.01</mu1>
    <mu2>0.01</mu2>
    <kp>1000000.0</kp>
    <kd>100.0</kd>
    <minDepth>0.001</minDepth>
    <maxVel>1.0</maxVel>
    <material>Gazebo/FlatBlack</material>
  </gazebo>
  <gazebo reference="caster_front_right_link">
    <mu1>0.01</mu1>
    <mu2>0.01</mu2>
    <kp>1000000.0</kp>
    <kd>100.0</kd>
    <minDepth>0.001</minDepth>
    <maxVel>1.0</maxVel>
    <material>Gazebo/FlatBlack</material>
  </gazebo>
  <gazebo reference="caster_front_left_link">
    <mu1>0.01</mu1>
    <mu2>0.01</mu2>
    <kp>1000000.0</kp>
    <kd>100.0</kd>
    <minDepth>0.001</minDepth>
    <maxVel>1.0</maxVel>
    <material>Gazebo/FlatBlack</material>
  </gazebo>
  <gazebo reference="imu_link">
    <sensor name="imu" type="imu">
      <always_on>true</always_on>
      <visualize>false</visualize>
    </sensor>
    <material>Gazebo/Grey</material>
  </gazebo>
  <gazebo>
    <plugin filename="libgazebo_ros_diff_drive.so" name="moving_base_controller">
      <commandTopic>cmd_vel</commandTopic>
      <odometryTopic>odom</odometryTopic>
      <odometryFrame>odom</odometryFrame>
      <odometrySource>world</odometrySource>
      <publishOdomTF>true</publishOdomTF>
      <robotBaseFrame>base_footprint</robotBaseFrame>
      <publishWheelTF>false</publishWheelTF>
      <publishTf>true</publishTf>
      <publishWheelJointState>true</publishWheelJointState>
      <legacyMode>false</legacyMode>
      <updateRate>30</updateRate>
      <leftJoint>wheel_left_joint</leftJoint>
      <rightJoint>wheel_right_joint</rightJoint>
      <wheelSeparation>0.650</wheelSeparation>
      <wheelDiameter>0.168</wheelDiameter>
      <wheelAcceleration>1</wheelAcceleration>
      <wheelTorque>50</wheelTorque>
      <rosDebugLevel>na</rosDebugLevel>
    </plugin>
  </gazebo>
  <gazebo>
    <plugin filename="libgazebo_ros_imu.so" name="imu_plugin">
      <alwaysOn>true</alwaysOn>
      <bodyName>imu_link</bodyName>
      <frameName>imu_link</frameName>
      <topicName>imu</topicName>
      <serviceName>imu_service</serviceName>
      <gaussianNoise>0.0</gaussianNoise>
      <updateRate>0</updateRate>
      <imu>
        <noise>
          <type>gaussian</type>
          <rate>
            <mean>0.0</mean>
            <stddev>2e-4</stddev>
            <bias_mean>0.0000075</bias_mean>
            <bias_stddev>0.0000008</bias_stddev>
          </rate>
          <accel>
            <mean>0.0</mean>
            <stddev>1.7e-2</stddev>
            <bias_mean>0.1</bias_mean>
            <bias_stddev>0.001</bias_stddev>
          </accel>
        </noise>
      </imu>
    </plugin>
  </gazebo>
  <joint name="camera_mb_joint" type="fixed">
    <origin xyz="-0.3417345036929093 0.14581973548828592 0.8711514337998042" rpy="-0.00041233477833903736 0.0008236868957589115 3.135073951633916"/>
    <parent link="base_link_mb"/>
    <child link="camera_mb_link"/>
  </joint>
  <link name="camera_mb_link">
    <inertial>
      <origin xyz="0.0 0.0 0.0" rpy="0 0 0"/>
      <mass value="0.564"/>
      <inertia ixx="0.003881243" ixy="0.0" ixz="0.0" iyy="0.00049894" iyz="0.0" izz="0.003879257"/>
    </inertial>
    <collision>
      <origin xyz="-0.01 -0.06 0.0" rpy="0.0 0.0 0.0"/>
      <geometry>
        <box size="0.04 0.165 0.03"/>
      </geometry>
    </collision>
  </link>
  <gazebo reference="camera_mb_link">
    <selfCollide>false</selfCollide>
  </gazebo>
  <joint name="camera_mb_rgb_joint" type="fixed">
    <origin xyz="0.0 -0.045 0.0" rpy="0.0 0.0 0.0"/>
    <parent link="camera_mb_link"/>
    <child link="camera_mb_rgb_frame"/>
  </joint>
  <link name="camera_mb_rgb_frame"/>
  <joint name="camera_mb_rgb_optical_joint" type="fixed">
    <origin xyz="0.0 0.0 0.0" rpy="-1.5707963267948966 0.0 -1.5707963267948966"/>
    <parent link="camera_mb_rgb_frame"/>
    <child link="camera_mb_rgb_optical_frame"/>
  </joint>
  <link name="camera_mb_rgb_optical_frame">
    <visual>
      <origin xyz="0.0 0.0 -0.03" rpy="1.5707963267948966 0.0 0.0"/>
      <geometry>
        <mesh filename="package://t2rgb_description/meshes/sensors/astra2.dae" scale="1.0 1.0 1.0"/>
      </geometry>
    </visual>
  </link>
  <joint name="camera_mb_depth_joint" type="fixed">
    <origin xyz="0.0 -0.02 0.0" rpy="0.0 0.0 0.0"/>
    <parent link="camera_mb_link"/>
    <child link="camera_mb_depth_frame"/>
  </joint>
  <link name="camera_mb_depth_frame"/>
  <joint name="camera_mb_depth_optical_joint" type="fixed">
    <origin xyz="0.0 0.0 0.0" rpy="-1.5707963267948966 0.0 -1.5707963267948966"/>
    <parent link="camera_mb_depth_frame"/>
    <child link="camera_mb_depth_optical_frame"/>
  </joint>
  <link name="camera_mb_depth_optical_frame"/>
  <gazebo reference="camera_mb_depth_frame">
    <sensor name="camera" type="depth">
      <always_on>true</always_on>
      <update_rate>20.0</update_rate>
      <camera>
        <horizontal_fov>1.0471975511965976</horizontal_fov>
        <image>
          <format>B8G8R8</format>
          <width>640</width>
          <height>480</height>
        </image>
        <clip>
          <near>0.10</near>
          <far>8.0</far>
        </clip>
      </camera>
      <plugin filename="libgazebo_ros_openni_kinect.so" name="camera_mb_camera_controller">
        <cameraName>camera_mb</cameraName>
        <alwaysOn>true</alwaysOn>
        <updateRate>10</updateRate>
        <imageTopicName>rgb/image_raw</imageTopicName>
        <depthImageTopicName>depth/image_raw</depthImageTopicName>
        <pointCloudTopicName>depth/points</pointCloudTopicName>
        <cameraInfoTopicName>rgb/camera_info</cameraInfoTopicName>
        <depthImageCameraInfoTopicName>depth/camera_info</depthImageCameraInfoTopicName>
        <frameName>camera_mb_depth_optical_frame</frameName>
        <baseline>0.1</baseline>
        <distortion_k1>0.0</distortion_k1>
        <distortion_k2>0.0</distortion_k2>
        <distortion_k3>0.0</distortion_k3>
        <distortion_t1>0.0</distortion_t1>
        <distortion_t2>0.0</distortion_t2>
        <pointCloudCutoff>0.4</pointCloudCutoff>
      </plugin>
    </sensor>
  </gazebo>
  <link name="base_footprint"/>
  <joint name="base_joint" type="fixed">
    <origin xyz="0.0 0.0 0.01" rpy="0.0 0.0 0.0"/>
    <parent link="base_footprint"/>
    <child link="base_link_mb"/>
  </joint>
  <link name="base_link_mb">
    <visual>
      <origin xyz="-0.43 -0.33 0.03" rpy="1.57 0.0 1.57"/>
      <geometry>
        <mesh filename="package://ur_e_description/meshes/moving_base/moving_base.STL" scale="0.001 0.001 0.001"/>
      </geometry>
      <material name="light_black"/>
    </visual>
    <collision>
      <origin xyz="0.0 0.0 0.459" rpy="0.0 0.0 0.0"/>
      <geometry>
        <box size="0.9 0.6 0.77"/>
      </geometry>
    </collision>
  </link>
  <link name="inertial_link">
    <inertial>
      <origin xyz="-0.00065 -0.085 0.062" rpy="0 0 0"/>
      <mass value="100.0"/>
      <inertia ixx="0.6022" ixy="-0.02364" ixz="-0.1197" iyy="1.7386" iyz="-0.001544" izz="2.0296"/>
    </inertial>
  </link>
  <joint name="inertial_joint" type="fixed">
    <origin xyz="0.0 0.0 0.0" rpy="0.0 0.0 0.0"/>
    <parent link="base_link_mb"/>
    <child link="inertial_link"/>
  </joint>
  <joint name="wheel_left_joint" type="continuous">
    <origin xyz="0.0 0.325 0.074" rpy="-1.57 0.0 0.0"/>
    <axis xyz="0.0 0.0 1.0"/>
    <parent link="base_link_mb"/>
    <child link="wheel_left_link"/>
  </joint>
  <link name="wheel_left_link">
    <inertial>
      <origin xyz="0.0 0.0 0.0" rpy="0 0 0"/>
      <mass value="2.637"/>
      <inertia ixx="0.02467" ixy="0.0" ixz="0.0" iyy="0.04411" iyz="0.0" izz="0.02467"/>
    </inertial>
    <visual>
      <origin xyz="0.0 0.0 -0.055" rpy="-1.57 0.0 0.0"/>
      <geometry>
        <mesh filename="package://ur_e_description/meshes/wheels/left_tire.stl" scale="0.0025 0.0025 0.0025"/>
      </geometry>
      <material name="dark"/>
    </visual>
    <collision>
      <origin xyz="0.0 0.0 0.0" rpy="0.0 0.0 0.0"/>
      <geometry>
        <cylinder radius="0.084" length="0.044"/>
      </geometry>
    </collision>
  </link>
  <joint name="wheel_right_joint" type="continuous">
    <origin xyz="0.0 -0.325 0.074" rpy="-1.57 0.0 0.0"/>
    <axis xyz="0.0 0.0 1.0"/>
    <parent link="base_link_mb"/>
    <child link="wheel_right_link"/>
  </joint>
  <link name="wheel_right_link">
    <inertial>
      <origin xyz="0.0 0.0 0.0" rpy="0 0 0"/>
      <mass value="2.637"/>
      <inertia ixx="0.02467" ixy="0.0" ixz="0.0" iyy="0.04411" iyz="0.0" izz="0.02467"/>
    </inertial>
    <visual>
      <origin xyz="0.0 0.0 0.055" rpy="1.57 0.0 0.0"/>
      <geometry>
        <mesh filename="package://ur_e_description/meshes/wheels/left_tire.stl" scale="0.0025 0.0025 0.0025"/>
      </geometry>
      <material name="dark"/>
    </visual>
    <collision>
      <origin xyz="0.0 0.0 0.0" rpy="0.0 0.0 0.0"/>
      <geometry>
        <cylinder radius="0.084" length="0.044"/>
      </geometry>
    </collision>
  </link>
  <joint name="caster_back_right_joint" type="fixed">
    <origin xyz="-0.345 -0.19 -0.004" rpy="-1.57 0.0 0.0"/>
    <parent link="base_link_mb"/>
    <child link="caster_back_right_link"/>
  </joint>
  <link name="caster_back_right_link">
    <inertial>
      <origin xyz="0.0 0.0 0.0" rpy="0 0 0"/>
      <mass value="0.005"/>
      <inertia ixx="0.001" ixy="0.0" ixz="0.0" iyy="0.001" iyz="0.0" izz="0.001"/>
    </inertial>
    <visual>
      <origin xyz="0.027 -0.06 0.0" rpy="1.57 0.0 0.0"/>
      <geometry>
        <mesh filename="package://ur_e_description/meshes/wheels/left_tire.stl" scale="0.002 0.002 0.002"/>
      </geometry>
      <material name="dark"/>
    </visual>
    <collision>
      <origin xyz="0.0 0.001 0.0" rpy="0.0 0.0 0.0"/>
      <geometry>
        <box size="0.03 0.009 0.078"/>
      </geometry>
    </collision>
  </link>
  <joint name="caster_back_left_joint" type="fixed">
    <origin xyz="-0.345 0.19 -0.004" rpy="-1.57 0.0 0.0"/>
    <parent link="base_link_mb"/>
    <child link="caster_back_left_link"/>
  </joint>
  <link name="caster_back_left_link">
    <inertial>
      <origin xyz="0.0 0.0 0.0" rpy="0 0 0"/>
      <mass value="0.005"/>
      <inertia ixx="0.001" ixy="0.0" ixz="0.0" iyy="0.001" iyz="0.0" izz="0.001"/>
    </inertial>
    <visual>
      <origin xyz="0.027 -0.06 0.0" rpy="-1.57 0.0 0.0"/>
      <geometry>
        <mesh filename="package://ur_e_description/meshes/wheels/left_tire.stl" scale="0.002 0.002 0.002"/>
      </geometry>
      <material name="dark"/>
    </visual>
    <collision>
      <origin xyz="0.0 0.001 0.0" rpy="0.0 0.0 0.0"/>
      <geometry>
        <box size="0.03 0.009 0.078"/>
      </geometry>
    </collision>
  </link>
  <joint name="caster_front_right_joint" type="fixed">
    <origin xyz="0.345 -0.19 -0.004" rpy="-1.57 0.0 0.0"/>
    <parent link="base_link_mb"/>
    <child link="caster_front_right_link"/>
  </joint>
  <link name="caster_front_right_link">
    <inertial>
      <origin xyz="0.0 0.0 0.0" rpy="0 0 0"/>
      <mass value="0.005"/>
      <inertia ixx="0.001" ixy="0.0" ixz="0.0" iyy="0.001" iyz="0.0" izz="0.001"/>
    </inertial>
    <visual>
      <origin xyz="0.0 -0.06 0.0" rpy="1.57 0.0 0.0"/>
      <geometry>
        <mesh filename="package://ur_e_description/meshes/wheels/left_tire.stl" scale="0.002 0.002 0.002"/>
      </geometry>
      <material name="dark"/>
    </visual>
    <collision>
      <origin xyz="0.0 0.001 0.0" rpy="0.0 0.0 0.0"/>
      <geometry>
        <box size="0.03 0.009 0.078"/>
      </geometry>
    </collision>
  </link>
  <joint name="caster_front_left_joint" type="fixed">
    <origin xyz="0.345 0.19 -0.004" rpy="-1.57 0.0 0.0"/>
    <parent link="base_link_mb"/>
    <child link="caster_front_left_link"/>
  </joint>
  <link name="caster_front_left_link">
    <inertial>
      <origin xyz="0.0 0.0 0.0" rpy="0 0 0"/>
      <mass value="0.005"/>
      <inertia ixx="0.001" ixy="0.0" ixz="0.0" iyy="0.001" iyz="0.0" izz="0.001"/>
    </inertial>
    <visual>
      <origin xyz="0.0 -0.06 0.0" rpy="-1.57 0.0 0.0"/>
      <geometry>
        <mesh filename="package://ur_e_description/meshes/wheels/left_tire.stl" scale="0.002 0.002 0.002"/>
      </geometry>
      <material name="dark"/>
    </visual>
    <collision>
      <origin xyz="0.0 0.001 0.0" rpy="0.0 0.0 0.0"/>
      <geometry>
        <box size="0.03 0.009 0.078"/>
      </geometry>
    </collision>
  </link>
  <joint name="imu_joint" type="fixed">
    <origin xyz="0.0 0.0 0.068" rpy="0.0 0.0 0.0"/>
    <parent link="base_link_mb"/>
    <child link="imu_link"/>
  </joint>
  <link name="imu_link"/>
</robot>